<?xml version="1.0" encoding="utf-8"?>
<!-- This URDF was automatically created by SolidWorks to URDF Exporter! Originally created by Stephen Brawner (brawner@gmail.com) 
     Commit Version: 1.5.1-0-g916b5db  Build Version: 1.5.7152.31018
     For more information, please see http://wiki.ros.org/sw_urdf_exporter -->
<robot
  name="prototype_urdf2">
  <link
    name="base_link">
    <inertial>
      <origin
        xyz="4.8151E-05 0.14906 0.14691"
        rpy="0 0 0" />
      <mass
        value="5.1718" />
      <inertia
        ixx="0.012199"
        ixy="-3.0277E-07"
        ixz="-0.00011127"
        iyy="0.072636"
        iyz="1.8521E-06"
        izz="0.068154" />
    </inertial>
    <visual>
      <origin
        xyz="0 0 0"
        rpy="0 0 0" />
      <geometry>
        <mesh
          filename="package://prototype_urdf2/meshes/base_link.STL" />
      </geometry>
      <material
        name="">
        <color
          rgba="0.75294 0.75294 0.75294 1" />
      </material>
    </visual>
    <collision>
      <origin
        xyz="0 0 0"
        rpy="0 0 0" />
      <geometry>
        <mesh
          filename="package://prototype_urdf2/meshes/base_link.STL" />
      </geometry>
    </collision>
  </link>
  <link
    name="Front_Left_Upper_Arm">
    <inertial>
      <origin
        xyz="6.6613E-16 0.0147 0.005"
        rpy="0 0 0" />
      <mass
        value="0.035646" />
      <inertia
        ixx="3.835E-05"
        ixy="1.5009E-18"
        ixz="4.9911E-19"
        iyy="6.6493E-05"
        iyz="1.8691E-20"
        izz="0.00010426" />
    </inertial>
    <visual>
      <origin
        xyz="0 0 0"
        rpy="0 0 0" />
      <geometry>
        <mesh
          filename="package://prototype_urdf2/meshes/Front_Left_Upper_Arm.STL" />
      </geometry>
      <material
        name="">
        <color
          rgba="1 1 1 1" />
      </material>
    </visual>
    <collision>
      <origin
        xyz="0 0 0"
        rpy="0 0 0" />
      <geometry>
        <mesh
          filename="package://prototype_urdf2/meshes/Front_Left_Upper_Arm.STL" />
      </geometry>
    </collision>
  </link>
  <joint
    name="base_joint_FLUA"
    type="revolute">
    <origin
      xyz="0.15448 -0.14429 0.12049"
      rpy="-0.1407 0 -1.5726" />
    <parent
      link="base_link" />
    <child
      link="Front_Left_Upper_Arm" />
    <axis
      xyz="-1 0 0" />
    <limit
      lower="0"
      upper="0"
      effort="0"
      velocity="0" />
  </joint>
  <link
    name="Front_Left_Wheel_Connect_U">
    <inertial>
      <origin
        xyz="1.9429E-16 -0.011825 -0.0047437"
        rpy="0 0 0" />
      <mass
        value="4.2725E-05" />
      <inertia
        ixx="4.0077E-08"
        ixy="-4.7098E-23"
        ixz="1.4089E-23"
        iyy="4.5681E-08"
        iyz="-1.4715E-09"
        izz="2.8052E-08" />
    </inertial>
    <visual>
      <origin
        xyz="0 0 0"
        rpy="0 0 0" />
      <geometry>
        <mesh
          filename="package://prototype_urdf2/meshes/Front_Left_Wheel_Connect_U.STL" />
      </geometry>
      <material
        name="">
        <color
          rgba="1 0 0 1" />
      </material>
    </visual>
    <collision>
      <origin
        xyz="0 0 0"
        rpy="0 0 0" />
      <geometry>
        <mesh
          filename="package://prototype_urdf2/meshes/Front_Left_Wheel_Connect_U.STL" />
      </geometry>
    </collision>
  </link>
  <joint
    name="FLUA_joint_FLWC"
    type="revolute">
    <origin
      xyz="0 0.084743 -0.032957"
      rpy="0.1407 0 0" />
    <parent
      link="Front_Left_Upper_Arm" />
    <child
      link="Front_Left_Wheel_Connect_U" />
    <axis
      xyz="1 0 0" />
    <limit
      lower="0"
      upper="0"
      effort="0"
      velocity="0" />
  </joint>
  <link
    name="Front_Left_Wheel">
    <inertial>
      <origin
        xyz="1.4086E-06 -0.018579 -3.15E-05"
        rpy="0 0 0" />
      <mass
        value="0.0005833" />
      <inertia
        ixx="8.6958E-07"
        ixy="1.2157E-11"
        ixz="-1.9549E-11"
        iyy="1.6137E-06"
        iyz="-2.7388E-10"
        izz="8.6989E-07" />
    </inertial>
    <visual>
      <origin
        xyz="0 0 0"
        rpy="0 0 0" />
      <geometry>
        <mesh
          filename="package://prototype_urdf2/meshes/Front_Left_Wheel.STL" />
      </geometry>
      <material
        name="">
        <color
          rgba="1 0 0 1" />
      </material>
    </visual>
    <collision>
      <origin
        xyz="0 0 0"
        rpy="0 0 0" />
      <geometry>
        <mesh
          filename="package://prototype_urdf2/meshes/Front_Left_Wheel.STL" />
      </geometry>
    </collision>
  </link>
  <joint
    name="FLWC_joint_FLW"
    type="continuous">
    <origin
      xyz="0 0 0"
      rpy="0 0.87883 -3.1416" />
    <parent
      link="Front_Left_Wheel_Connect_U" />
    <child
      link="Front_Left_Wheel" />
    <axis
      xyz="0 1 0" />
    <limit
      effort="3.1"
      velocity="7" />
    <dynamics
      damping="0"
      friction="0" />
  </joint>
  <link
    name="Front_Left_Lower_Arm">
    <inertial>
      <origin
        xyz="-2.7756E-17 0.013612 0.0065523"
        rpy="0 0 0" />
      <mass
        value="0.037752" />
      <inertia
        ixx="2.6733E-05"
        ixy="-1.1805E-19"
        ixz="-7.6023E-20"
        iyy="6.0063E-05"
        iyz="-2.223E-07"
        izz="8.5645E-05" />
    </inertial>
    <visual>
      <origin
        xyz="0 0 0"
        rpy="0 0 0" />
      <geometry>
        <mesh
          filename="package://prototype_urdf2/meshes/Front_Left_Lower_Arm.STL" />
      </geometry>
      <material
        name="">
        <color
          rgba="1 1 1 1" />
      </material>
    </visual>
    <collision>
      <origin
        xyz="0 0 0"
        rpy="0 0 0" />
      <geometry>
        <mesh
          filename="package://prototype_urdf2/meshes/Front_Left_Lower_Arm.STL" />
      </geometry>
    </collision>
  </link>
  <joint
    name="base_joint_FLLA"
    type="revolute">
    <origin
      xyz="0.14944 -0.14428 0.047772"
      rpy="-0.21347 0 -1.5726" />
    <parent
      link="base_link" />
    <child
      link="Front_Left_Lower_Arm" />
    <axis
      xyz="1 0 0" />
    <limit
      lower="0"
      upper="0"
      effort="0"
      velocity="0" />
  </joint>
  <link
    name="Front_Left_Wheel_Connect_L">
    <inertial>
      <origin
        xyz="1.66533453693773E-16 -0.01182470467978 -0.00474369285104252"
        rpy="0 0 0" />
      <mass
        value="4.27254738673187E-05" />
      <inertia
        ixx="4.00769893258482E-08"
        ixy="-3.38045451895694E-23"
        ixz="1.64898971111911E-23"
        iyy="4.56805348900452E-08"
        iyz="-1.47149337236907E-09"
        izz="2.805162477184E-08" />
    </inertial>
    <visual>
      <origin
        xyz="0 0 0"
        rpy="0 0 0" />
      <geometry>
        <mesh
          filename="package://prototype_urdf2/meshes/Front_Left_Wheel_Connect_L.STL" />
      </geometry>
      <material
        name="">
        <color
          rgba="1 0 0 1" />
      </material>
    </visual>
    <collision>
      <origin
        xyz="0 0 0"
        rpy="0 0 0" />
      <geometry>
        <mesh
          filename="package://prototype_urdf2/meshes/Front_Left_Wheel_Connect_L.STL" />
      </geometry>
    </collision>
  </link>
  <joint
    name="FLLA_joint_FLWC"
    type="revolute">
    <origin
      xyz="0 0.076435 0.045428"
      rpy="0.21347 0 0" />
    <parent
      link="Front_Left_Lower_Arm" />
    <child
      link="Front_Left_Wheel_Connect_L" />
    <axis
      xyz="-1 0 0" />
    <limit
      lower="0"
      upper="0"
      effort="0"
      velocity="0" />
  </joint>
  <link
    name="Front_Left_Suspension">
    <inertial>
      <origin
        xyz="-0.02505 0.0053253 0.057836"
        rpy="0 0 0" />
      <mass
        value="0.097501" />
      <inertia
        ixx="7.9254E-06"
        ixy="2.402E-09"
        ixz="2.0772E-08"
        iyy="1.8592E-05"
        iyz="-7.2341E-07"
        izz="1.2438E-05" />
    </inertial>
    <visual>
      <origin
        xyz="0 0 0"
        rpy="0 0 0" />
      <geometry>
        <mesh
          filename="package://prototype_urdf2/meshes/Front_Left_Suspension.STL" />
      </geometry>
      <material
        name="">
        <color
          rgba="0.75294 0.75294 0.75294 1" />
      </material>
    </visual>
    <collision>
      <origin
        xyz="0 0 0"
        rpy="0 0 0" />
      <geometry>
        <mesh
          filename="package://prototype_urdf2/meshes/Front_Left_Suspension.STL" />
      </geometry>
    </collision>
  </link>
  <joint
    name="base_joint_FLS"
    type="prismatic">
    <origin
      xyz="0.16284 -0.086237 0.1322"
      rpy="-1.4553 -1.1874 3.1397" />
    <parent
      link="base_link" />
    <child
      link="Front_Left_Suspension" />
    <axis
      xyz="0 -0.11521 -0.99334" />
    <limit
      lower="-0.04"
      upper="0"
      effort="1000"
      velocity="1000" />
    <dynamics
      damping="0"
      friction="0" />
  </joint>
  <link
    name="Front_Left_Lower_Arm_S">
    <inertial>
      <origin
        xyz="-2.77555756156289E-17 0.013612079592021 0.00655228418322651"
        rpy="0 0 0" />
      <mass
        value="0.0377520303994239" />
      <inertia
        ixx="2.67333578708892E-05"
        ixy="-1.1777728433775E-19"
        ixz="-7.73430416349332E-20"
        iyy="6.00628817070965E-05"
        iyz="-2.22296810574117E-07"
        izz="8.56446705491993E-05" />
    </inertial>
    <visual>
      <origin
        xyz="0 0 0"
        rpy="0 0 0" />
      <geometry>
        <mesh
          filename="package://prototype_urdf2/meshes/Front_Left_Lower_Arm_S.STL" />
      </geometry>
      <material
        name="">
        <color
          rgba="1 1 1 1" />
      </material>
    </visual>
    <collision>
      <origin
        xyz="0 0 0"
        rpy="0 0 0" />
      <geometry>
        <mesh
          filename="package://prototype_urdf2/meshes/Front_Left_Lower_Arm_S.STL" />
      </geometry>
    </collision>
  </link>
  <joint
    name="FLS_joint_FLLA"
    type="fixed">
    <origin
      xyz="-0.073326 0.050307 0.052619"
      rpy="0.97395 -1.4553 1.5708" />
    <parent
      link="Front_Left_Suspension" />
    <child
      link="Front_Left_Lower_Arm_S" />
    <axis
      xyz="0 0 0" />
    <dynamics
      damping="0"
      friction="0" />
  </joint>
  <link
    name="Back_Left_Upper_Arm">
    <inertial>
      <origin
        xyz="2.77555756156289E-17 -0.0147001536622141 -0.005"
        rpy="0 0 0" />
      <mass
        value="0.0356457256760713" />
      <inertia
        ixx="3.83497573600796E-05"
        ixy="-8.08469759769435E-20"
        ixz="-2.31852808455335E-20"
        iyy="6.64927053825921E-05"
        iyz="-2.71050543121376E-20"
        izz="0.000104259142609384" />
    </inertial>
    <visual>
      <origin
        xyz="0 0 0"
        rpy="0 0 0" />
      <geometry>
        <mesh
          filename="package://prototype_urdf2/meshes/Back_Left_Upper_Arm.STL" />
      </geometry>
      <material
        name="">
        <color
          rgba="1 1 1 1" />
      </material>
    </visual>
    <collision>
      <origin
        xyz="0 0 0"
        rpy="0 0 0" />
      <geometry>
        <mesh
          filename="package://prototype_urdf2/meshes/Back_Left_Upper_Arm.STL" />
      </geometry>
    </collision>
  </link>
  <joint
    name="base_joint_BLUA"
    type="revolute">
    <origin
      xyz="0.15447 0.135 0.12049"
      rpy="3.0009 0 -1.5708" />
    <parent
      link="base_link" />
    <child
      link="Back_Left_Upper_Arm" />
    <axis
      xyz="1 0 0" />
    <limit
      lower="0"
      upper="0"
      effort="0"
      velocity="0" />
  </joint>
  <link
    name="Back_Left_Wheel_Connect_U">
    <inertial>
      <origin
        xyz="-1.3878E-16 0.011825 0.0047439"
        rpy="0 0 0" />
      <mass
        value="4.2725E-05" />
      <inertia
        ixx="4.0077E-08"
        ixy="-2.4975E-23"
        ixz="6.5432E-24"
        iyy="4.5681E-08"
        iyz="-1.4715E-09"
        izz="2.8052E-08" />
    </inertial>
    <visual>
      <origin
        xyz="0 0 0"
        rpy="0 0 0" />
      <geometry>
        <mesh
          filename="package://prototype_urdf2/meshes/Back_Left_Wheel_Connect_U.STL" />
      </geometry>
      <material
        name="">
        <color
          rgba="1 0 0 1" />
      </material>
    </visual>
    <collision>
      <origin
        xyz="0 0 0"
        rpy="0 0 0" />
      <geometry>
        <mesh
          filename="package://prototype_urdf2/meshes/Back_Left_Wheel_Connect_U.STL" />
      </geometry>
    </collision>
  </link>
  <joint
    name="BLUA_joint_BLWC"
    type="revolute">
    <origin
      xyz="0 -0.084743 0.032957"
      rpy="0.1407 0 0" />
    <parent
      link="Back_Left_Upper_Arm" />
    <child
      link="Back_Left_Wheel_Connect_U" />
    <axis
      xyz="1 0 0" />
    <limit
      lower="0"
      upper="0"
      effort="0"
      velocity="0" />
  </joint>
  <link
    name="Back_Left_Wheel">
    <inertial>
      <origin
        xyz="1.40862745898196E-06 -0.0185785956024857 -3.13163303364006E-05"
        rpy="0 0 0" />
      <mass
        value="0.000583296678332389" />
      <inertia
        ixx="8.6958020227038E-07"
        ixy="1.2156654097372E-11"
        ixz="-1.95489792553624E-11"
        iyy="1.61370446750533E-06"
        iyz="-2.73880661125538E-10"
        izz="8.69890840625022E-07" />
    </inertial>
    <visual>
      <origin
        xyz="0 0 0"
        rpy="0 0 0" />
      <geometry>
        <mesh
          filename="package://prototype_urdf2/meshes/Back_Left_Wheel.STL" />
      </geometry>
      <material
        name="">
        <color
          rgba="1 0 0 1" />
      </material>
    </visual>
    <collision>
      <origin
        xyz="0 0 0"
        rpy="0 0 0" />
      <geometry>
        <mesh
          filename="package://prototype_urdf2/meshes/Back_Left_Wheel.STL" />
      </geometry>
    </collision>
  </link>
  <joint
    name="BLWC_joint_BLW"
    type="continuous">
    <origin
      xyz="0 0 0"
      rpy="0 0 0" />
    <parent
      link="Back_Left_Wheel_Connect_U" />
    <child
      link="Back_Left_Wheel" />
    <axis
      xyz="0 1 0" />
    <limit
      effort="3.1"
      velocity="7" />
  </joint>
  <link
    name="Back_Left_Lower_Arm">
    <inertial>
      <origin
        xyz="2.77555756156289E-17 -0.0136120795920238 -0.00655228418322451"
        rpy="0 0 0" />
      <mass
        value="0.0377520303994239" />
      <inertia
        ixx="2.67333578708892E-05"
        ixy="-1.0339645159441E-19"
        ixz="-5.57410387269857E-20"
        iyy="6.00628817070965E-05"
        iyz="-2.22296810574141E-07"
        izz="8.56446705491993E-05" />
    </inertial>
    <visual>
      <origin
        xyz="0 0 0"
        rpy="0 0 0" />
      <geometry>
        <mesh
          filename="package://prototype_urdf2/meshes/Back_Left_Lower_Arm.STL" />
      </geometry>
      <material
        name="">
        <color
          rgba="1 1 1 1" />
      </material>
    </visual>
    <collision>
      <origin
        xyz="0 0 0"
        rpy="0 0 0" />
      <geometry>
        <mesh
          filename="package://prototype_urdf2/meshes/Back_Left_Lower_Arm.STL" />
      </geometry>
    </collision>
  </link>
  <joint
    name="base_joint_BLLA"
    type="revolute">
    <origin
      xyz="0.14944 0.135 0.047772"
      rpy="2.9281 0 -1.5708" />
    <parent
      link="base_link" />
    <child
      link="Back_Left_Lower_Arm" />
    <axis
      xyz="1 0 0" />
    <limit
      lower="0"
      upper="0"
      effort="0"
      velocity="0" />
  </joint>
  <link
    name="Back_Left_Wheel_Connect_L">
    <inertial>
      <origin
        xyz="-1.38777878078145E-16 0.0118247046797822 0.00474387706085233"
        rpy="0 0 0" />
      <mass
        value="4.27254738673186E-05" />
      <inertia
        ixx="4.0076989325848E-08"
        ixy="-2.49245205610583E-23"
        ixz="6.44597877411744E-24"
        iyy="4.56805348900451E-08"
        iyz="-1.47149337236906E-09"
        izz="2.805162477184E-08" />
    </inertial>
    <visual>
      <origin
        xyz="0 0 0"
        rpy="0 0 0" />
      <geometry>
        <mesh
          filename="package://prototype_urdf2/meshes/Back_Left_Wheel_Connect_L.STL" />
      </geometry>
      <material
        name="">
        <color
          rgba="1 0 0 1" />
      </material>
    </visual>
    <collision>
      <origin
        xyz="0 0 0"
        rpy="0 0 0" />
      <geometry>
        <mesh
          filename="package://prototype_urdf2/meshes/Back_Left_Wheel_Connect_L.STL" />
      </geometry>
    </collision>
  </link>
  <joint
    name="BLLA_joint_BLWC"
    type="revolute">
    <origin
      xyz="0 -0.076435 -0.045428"
      rpy="0.21347 0 0" />
    <parent
      link="Back_Left_Lower_Arm" />
    <child
      link="Back_Left_Wheel_Connect_L" />
    <axis
      xyz="-1 0 0" />
    <limit
      lower="0"
      upper="0"
      effort="0"
      velocity="0" />
  </joint>
  <link
    name="Back_Left_Suspension">
    <inertial>
      <origin
        xyz="-0.0250501195396812 0.00532528573434377 0.0578364361373781"
        rpy="0 0 0" />
      <mass
        value="0.0975010516337178" />
      <inertia
        ixx="7.92535130270424E-06"
        ixy="2.40205751875798E-09"
        ixz="2.07721001720025E-08"
        iyy="1.85918479783726E-05"
        iyz="-7.23412240509213E-07"
        izz="1.24383810777078E-05" />
    </inertial>
    <visual>
      <origin
        xyz="0 0 0"
        rpy="0 0 0" />
      <geometry>
        <mesh
          filename="package://prototype_urdf2/meshes/Back_Left_Suspension.STL" />
      </geometry>
      <material
        name="">
        <color
          rgba="0.752941176470588 0.752941176470588 0.752941176470588 1" />
      </material>
    </visual>
    <collision>
      <origin
        xyz="0 0 0"
        rpy="0 0 0" />
      <geometry>
        <mesh
          filename="package://prototype_urdf2/meshes/Back_Left_Suspension.STL" />
      </geometry>
    </collision>
  </link>
  <joint
    name="base_joint_BLS"
    type="prismatic">
    <origin
      xyz="0.16528 0.076934 0.13323"
      rpy="1.6863 -1.1874 -3.1416" />
    <parent
      link="base_link" />
    <child
      link="Back_Left_Suspension" />
    <axis
      xyz="0 -0.11521 -0.99334" />
    <limit
      lower="-0.04"
      upper="0"
      effort="1000"
      velocity="1000" />
    <dynamics
      damping="0"
      friction="0" />
  </joint>
  <link
    name="Back_Left_Upper_Arm_S">
    <inertial>
      <origin
        xyz="5.8287E-16 -0.013612 -0.0065523"
        rpy="0 0 0" />
      <mass
        value="0.037752" />
      <inertia
        ixx="2.6733E-05"
        ixy="-1.0752E-19"
        ixz="-5.4113E-20"
        iyy="6.0063E-05"
        iyz="-2.223E-07"
        izz="8.5645E-05" />
    </inertial>
    <visual>
      <origin
        xyz="0 0 0"
        rpy="0 0 0" />
      <geometry>
        <mesh
          filename="package://prototype_urdf2/meshes/Back_Left_Upper_Arm_S.STL" />
      </geometry>
      <material
        name="">
        <color
          rgba="1 1 1 1" />
      </material>
    </visual>
    <collision>
      <origin
        xyz="0 0 0"
        rpy="0 0 0" />
      <geometry>
        <mesh
          filename="package://prototype_urdf2/meshes/Back_Left_Upper_Arm_S.STL" />
      </geometry>
    </collision>
  </link>
  <joint
    name="BLS_joint_BLUA"
    type="fixed">
    <origin
      xyz="-0.073326 -0.039657 0.063053"
      rpy="0.97395 1.4553 -1.5708" />
    <parent
      link="Back_Left_Suspension" />
    <child
      link="Back_Left_Upper_Arm_S" />
    <axis
      xyz="-1 0 0" />
  </joint>
  <link
    name="Front_Right_Upper_Arm">
    <inertial>
      <origin
        xyz="-1.11022302462516E-16 0.0147001536622058 0.00499999999999509"
        rpy="0 0 0" />
      <mass
        value="0.0356457256760713" />
      <inertia
        ixx="3.83497573600796E-05"
        ixy="1.17433177202928E-19"
        ixz="-1.48348225416485E-19"
        iyy="6.64927053825921E-05"
        iyz="-2.47566530101826E-20"
        izz="0.000104259142609384" />
    </inertial>
    <visual>
      <origin
        xyz="0 0 0"
        rpy="0 0 0" />
      <geometry>
        <mesh
          filename="package://prototype_urdf2/meshes/Front_Right_Upper_Arm.STL" />
      </geometry>
      <material
        name="">
        <color
          rgba="1 1 1 1" />
      </material>
    </visual>
    <collision>
      <origin
        xyz="0 0 0"
        rpy="0 0 0" />
      <geometry>
        <mesh
          filename="package://prototype_urdf2/meshes/Front_Right_Upper_Arm.STL" />
      </geometry>
    </collision>
  </link>
  <joint
    name="base_joint_FRUA"
    type="revolute">
    <origin
      xyz="-0.15588 -0.14371 0.13039"
      rpy="-3.0009 0 -1.5726" />
    <parent
      link="base_link" />
    <child
      link="Front_Right_Upper_Arm" />
    <axis
      xyz="1 0 0" />
    <limit
      lower="0"
      upper="0"
      effort="0"
      velocity="0" />
  </joint>
  <link
    name="Front_Right_Wheel_Connect_U">
    <inertial>
      <origin
        xyz="-1.41553435639707E-15 -0.0118247046797807 -0.00474369285104376"
        rpy="0 0 0" />
      <mass
        value="4.27254738673187E-05" />
      <inertia
        ixx="4.00769893258482E-08"
        ixy="6.45672629234458E-22"
        ixz="-1.60242471358E-22"
        iyy="4.56805348900447E-08"
        iyz="-1.47149337237219E-09"
        izz="2.80516247718406E-08" />
    </inertial>
    <visual>
      <origin
        xyz="0 0 0"
        rpy="0 0 0" />
      <geometry>
        <mesh
          filename="package://prototype_urdf2/meshes/Front_Right_Wheel_Connect_U.STL" />
      </geometry>
      <material
        name="">
        <color
          rgba="1 0 0 1" />
      </material>
    </visual>
    <collision>
      <origin
        xyz="0 0 0"
        rpy="0 0 0" />
      <geometry>
        <mesh
          filename="package://prototype_urdf2/meshes/Front_Right_Wheel_Connect_U.STL" />
      </geometry>
    </collision>
  </link>
  <joint
    name="FRUA_joint_FRWC"
    type="revolute">
    <origin
      xyz="0 0.084743 0.042957"
      rpy="-3.0009 0 3.1416" />
    <parent
      link="Front_Right_Upper_Arm" />
    <child
      link="Front_Right_Wheel_Connect_U" />
    <axis
      xyz="-1 0 0" />
    <limit
      lower="0"
      upper="0"
      effort="0"
      velocity="0" />
  </joint>
  <link
    name="Front_Right_Wheel">
    <inertial>
      <origin
        xyz="1.4086323996132E-06 -0.0185785955621235 -3.15006737992771E-05"
        rpy="0 0 0" />
      <mass
        value="0.000583296673656307" />
      <inertia
        ixx="8.69580200457977E-07"
        ixy="1.21569821151188E-11"
        ixz="-1.95491137831547E-11"
        iyy="1.61370446559763E-06"
        iyz="-2.73881322125108E-10"
        izz="8.69890839854235E-07" />
    </inertial>
    <visual>
      <origin
        xyz="0 0 0"
        rpy="0 0 0" />
      <geometry>
        <mesh
          filename="package://prototype_urdf2/meshes/Front_Right_Wheel.STL" />
      </geometry>
      <material
        name="">
        <color
          rgba="1 0 0 1" />
      </material>
    </visual>
    <collision>
      <origin
        xyz="0 0 0"
        rpy="0 0 0" />
      <geometry>
        <mesh
          filename="package://prototype_urdf2/meshes/Front_Right_Wheel.STL" />
      </geometry>
    </collision>
  </link>
  <joint
    name="FRWC_joint_FRW"
    type="continuous">
    <origin
      xyz="0 0 0"
      rpy="3.1416 0.38134 0" />
    <parent
      link="Front_Right_Wheel_Connect_U" />
    <child
      link="Front_Right_Wheel" />
    <axis
      xyz="0 1 0" />
    <limit
      effort="3.1"
      velocity="7" />
  </joint>
  <link
    name="Front_Right_Lower_Arm">
    <inertial>
      <origin
        xyz="-9.71445146547012E-16 0.0136120795920207 0.00655228418323024"
        rpy="0 0 0" />
      <mass
        value="0.0377520303994239" />
      <inertia
        ixx="2.67333578708891E-05"
        ixy="-2.17577617859008E-18"
        ixz="-7.82215074454645E-19"
        iyy="6.00628817070964E-05"
        iyz="-2.22296810576787E-07"
        izz="8.56446705491991E-05" />
    </inertial>
    <visual>
      <origin
        xyz="0 0 0"
        rpy="0 0 0" />
      <geometry>
        <mesh
          filename="package://prototype_urdf2/meshes/Front_Right_Lower_Arm.STL" />
      </geometry>
      <material
        name="">
        <color
          rgba="1 1 1 1" />
      </material>
    </visual>
    <collision>
      <origin
        xyz="0 0 0"
        rpy="0 0 0" />
      <geometry>
        <mesh
          filename="package://prototype_urdf2/meshes/Front_Right_Lower_Arm.STL" />
      </geometry>
    </collision>
  </link>
  <joint
    name="base_joint_FRLA"
    type="revolute">
    <origin
      xyz="-0.14944 -0.14372 0.047772"
      rpy="-0.21347 0 1.5689" />
    <parent
      link="base_link" />
    <child
      link="Front_Right_Lower_Arm" />
    <axis
      xyz="1 0 0" />
    <limit
      lower="0"
      upper="0"
      effort="0"
      velocity="0" />
  </joint>
  <link
    name="Front_Right_Wheel_Connect_L">
    <inertial>
      <origin
        xyz="-1.41553435639707E-15 -0.0118247046797851 -0.00474369285103179"
        rpy="0 0 0" />
      <mass
        value="4.27254738673187E-05" />
      <inertia
        ixx="4.00769893258482E-08"
        ixy="6.45840650296383E-22"
        ixz="-1.60075258105049E-22"
        iyy="4.56805348900447E-08"
        iyz="-1.47149337237219E-09"
        izz="2.80516247718406E-08" />
    </inertial>
    <visual>
      <origin
        xyz="0 0 0"
        rpy="0 0 0" />
      <geometry>
        <mesh
          filename="package://prototype_urdf2/meshes/Front_Right_Wheel_Connect_L.STL" />
      </geometry>
      <material
        name="">
        <color
          rgba="1 0 0 1" />
      </material>
    </visual>
    <collision>
      <origin
        xyz="0 0 0"
        rpy="0 0 0" />
      <geometry>
        <mesh
          filename="package://prototype_urdf2/meshes/Front_Right_Wheel_Connect_L.STL" />
      </geometry>
    </collision>
  </link>
  <joint
    name="FRLA_joint_FRWC"
    type="revolute">
    <origin
      xyz="0 0.076435 0.045428"
      rpy="0.21347 0 0" />
    <parent
      link="Front_Right_Lower_Arm" />
    <child
      link="Front_Right_Wheel_Connect_L" />
    <axis
      xyz="-1 0 0" />
    <limit
      lower="0"
      upper="0"
      effort="0"
      velocity="0" />
  </joint>
  <link
    name="Front_Right_Suspension">
    <inertial>
      <origin
        xyz="-0.025050119534153 0.00532528572925309 0.0578364361376996"
        rpy="0 0 0" />
      <mass
        value="0.0975010516234581" />
      <inertia
        ixx="7.92535130195144E-06"
        ixy="2.4020624093064E-09"
        ixz="2.07721001697917E-08"
        iyy="1.8591847980283E-05"
        iyz="-7.23412238881963E-07"
        izz="1.24383810794388E-05" />
    </inertial>
    <visual>
      <origin
        xyz="0 0 0"
        rpy="0 0 0" />
      <geometry>
        <mesh
          filename="package://prototype_urdf2/meshes/Front_Right_Suspension.STL" />
      </geometry>
      <material
        name="">
        <color
          rgba="0.752941176470588 0.752941176470588 0.752941176470588 1" />
      </material>
    </visual>
    <collision>
      <origin
        xyz="0 0 0"
        rpy="0 0 0" />
      <geometry>
        <mesh
          filename="package://prototype_urdf2/meshes/Front_Right_Suspension.STL" />
      </geometry>
    </collision>
  </link>
  <joint
    name="base_joint_FRS"
    type="prismatic">
    <origin
      xyz="-0.16517 -0.08563 0.13323"
      rpy="1.6863 -1.1874 -0.0018512" />
    <parent
      link="base_link" />
    <child
      link="Front_Right_Suspension" />
    <axis
      xyz="0 -0.11521 -0.99334" />
    <limit
      lower="-0.04"
      upper="0"
      effort="1000"
      velocity="1000" />
  </joint>
  <link
    name="Front_Right_Lower_Arm_S">
    <inertial>
      <origin
        xyz="-1.02695629777827E-15 0.0136120795920232 0.0065522841832287"
        rpy="0 0 0" />
      <mass
        value="0.0377520303994238" />
      <inertia
        ixx="2.67333578708891E-05"
        ixy="-2.19549616439335E-18"
        ixz="-7.82830496830385E-19"
        iyy="6.00628817070964E-05"
        iyz="-2.22296810576787E-07"
        izz="8.56446705491992E-05" />
    </inertial>
    <visual>
      <origin
        xyz="0 0 0"
        rpy="0 0 0" />
      <geometry>
        <mesh
          filename="package://prototype_urdf2/meshes/Front_Right_Lower_Arm_S.STL" />
      </geometry>
      <material
        name="">
        <color
          rgba="1 1 1 1" />
      </material>
    </visual>
    <collision>
      <origin
        xyz="0 0 0"
        rpy="0 0 0" />
      <geometry>
        <mesh
          filename="package://prototype_urdf2/meshes/Front_Right_Lower_Arm_S.STL" />
      </geometry>
    </collision>
  </link>
  <joint
    name="FRS_joint_FRLA"
    type="fixed">
    <origin
      xyz="-0.073326 -0.039657 0.063053"
      rpy="-2.1676 1.4553 -1.5708" />
    <parent
      link="Front_Right_Suspension" />
    <child
      link="Front_Right_Lower_Arm_S" />
    <axis
      xyz="-1 0 0" />
  </joint>
  <link
    name="Back_Right_Upper_Arm">
    <inertial>
      <origin
        xyz="-2.77555756156289E-17 0.0127333626706839 0.00888571847345739"
        rpy="0 0 0" />
      <mass
        value="0.0356457256760713" />
      <inertia
        ixx="3.83497573600796E-05"
        ixy="1.20745472750592E-21"
        ixz="-5.73648270196137E-21"
        iyy="6.94053826276099E-05"
        iyz="-1.00756018977639E-05"
        izz="0.000101346465364366" />
    </inertial>
    <visual>
      <origin
        xyz="0 0 0"
        rpy="0 0 0" />
      <geometry>
        <mesh
          filename="package://prototype_urdf2/meshes/Back_Right_Upper_Arm.STL" />
      </geometry>
      <material
        name="">
        <color
          rgba="1 1 1 1" />
      </material>
    </visual>
    <collision>
      <origin
        xyz="0 0 0"
        rpy="0 0 0" />
      <geometry>
        <mesh
          filename="package://prototype_urdf2/meshes/Back_Right_Upper_Arm.STL" />
      </geometry>
    </collision>
  </link>
  <joint
    name="base_joint_BRUA"
    type="revolute">
    <origin
      xyz="-0.15588 0.135 0.13039"
      rpy="3.0009 0 -1.5708" />
    <parent
      link="base_link" />
    <child
      link="Back_Right_Upper_Arm" />
    <axis
      xyz="1 0 0" />
    <limit
      lower="0"
      upper="0"
      effort="0"
      velocity="0" />
  </joint>
  <link
    name="Back_Right_Wheel_Connect_U">
    <inertial>
      <origin
        xyz="-1.19348975147204E-15 0.0118246651845647 0.00474369285103651"
        rpy="0 0 0" />
      <mass
        value="4.27254738673186E-05" />
      <inertia
        ixx="4.00769893258481E-08"
        ixy="1.68109028574327E-24"
        ixz="-4.64395195790113E-24"
        iyy="4.56805348900451E-08"
        iyz="-1.47149337236923E-09"
        izz="2.80516247718401E-08" />
    </inertial>
    <visual>
      <origin
        xyz="0 0 0"
        rpy="0 0 0" />
      <geometry>
        <mesh
          filename="package://prototype_urdf2/meshes/Back_Right_Wheel_Connect_U.STL" />
      </geometry>
      <material
        name="">
        <color
          rgba="1 0 0 1" />
      </material>
    </visual>
    <collision>
      <origin
        xyz="0 0 0"
        rpy="0 0 0" />
      <geometry>
        <mesh
          filename="package://prototype_urdf2/meshes/Back_Right_Wheel_Connect_U.STL" />
      </geometry>
    </collision>
  </link>
  <joint
    name="BRUA_joint_BRWC"
    type="revolute">
    <origin
      xyz="0 0.069481 0.064801"
      rpy="-0.14071 0 3.1416" />
    <parent
      link="Back_Right_Upper_Arm" />
    <child
      link="Back_Right_Wheel_Connect_U" />
    <axis
      xyz="-1 0 0" />
    <limit
      lower="0"
      upper="0"
      effort="0"
      velocity="0" />
  </joint>
  <link
    name="Back_Right_Wheel">
    <inertial>
      <origin
        xyz="1.40862745938442E-06 -0.0185786350977028 -3.15005401522739E-05"
        rpy="0 0 0" />
      <mass
        value="0.000583296678332387" />
      <inertia
        ixx="8.69580202270378E-07"
        ixy="1.21566541036994E-11"
        ixz="-1.95489792557145E-11"
        iyy="1.61370446750533E-06"
        iyz="-2.73880661124133E-10"
        izz="8.69890840625018E-07" />
    </inertial>
    <visual>
      <origin
        xyz="0 0 0"
        rpy="0 0 0" />
      <geometry>
        <mesh
          filename="package://prototype_urdf2/meshes/Back_Right_Wheel.STL" />
      </geometry>
      <material
        name="">
        <color
          rgba="1 0 0 1" />
      </material>
    </visual>
    <collision>
      <origin
        xyz="0 0 0"
        rpy="0 0 0" />
      <geometry>
        <mesh
          filename="package://prototype_urdf2/meshes/Back_Right_Wheel.STL" />
      </geometry>
    </collision>
  </link>
  <joint
    name="BRWC_joint_BRW"
    type="continuous">
    <origin
      xyz="0 0 0"
      rpy="3.1416 0.26012 3.1416" />
    <parent
      link="Back_Right_Wheel_Connect_U" />
    <child
      link="Back_Right_Wheel" />
    <axis
      xyz="0 1 0" />
    <limit
      effort="3.1"
      velocity="7" />
  </joint>
  <link
    name="Back_Right_Lower_Arm">
    <inertial>
      <origin
        xyz="2.77555756156289E-17 -0.0151034357011666 -0.000327671875584697"
        rpy="0 0 0" />
      <mass
        value="0.0377520303994239" />
      <inertia
        ixx="2.67333578708892E-05"
        ixy="1.00807927757276E-20"
        ixz="-3.16035372917846E-21"
        iyy="6.42816105258092E-05"
        iyz="9.49601878939577E-06"
        izz="8.14259417304866E-05" />
    </inertial>
    <visual>
      <origin
        xyz="0 0 0"
        rpy="0 0 0" />
      <geometry>
        <mesh
          filename="package://prototype_urdf2/meshes/Back_Right_Lower_Arm.STL" />
      </geometry>
      <material
        name="">
        <color
          rgba="1 1 1 1" />
      </material>
    </visual>
    <collision>
      <origin
        xyz="0 0 0"
        rpy="0 0 0" />
      <geometry>
        <mesh
          filename="package://prototype_urdf2/meshes/Back_Right_Lower_Arm.STL" />
      </geometry>
    </collision>
  </link>
  <joint
    name="base_joint_BRLA"
    type="revolute">
    <origin
      xyz="-0.14944 0.135 0.047772"
      rpy="-2.9281 0 1.5708" />
    <parent
      link="base_link" />
    <child
      link="Back_Right_Lower_Arm" />
    <axis
      xyz="1 0 0" />
    <limit
      lower="0"
      upper="0"
      effort="0"
      velocity="0" />
  </joint>
  <link
    name="Back_Right_Wheel_Connect_L">
    <inertial>
      <origin
        xyz="-1.22124532708767E-15 0.0118246651845647 0.00474369285103653"
        rpy="0 0 0" />
      <mass
        value="4.27254738673186E-05" />
      <inertia
        ixx="4.00769893258481E-08"
        ixy="1.68389606891831E-24"
        ixz="-4.65712277444244E-24"
        iyy="4.56805348900451E-08"
        iyz="-1.47149337236923E-09"
        izz="2.805162477184E-08" />
    </inertial>
    <visual>
      <origin
        xyz="0 0 0"
        rpy="0 0 0" />
      <geometry>
        <mesh
          filename="package://prototype_urdf2/meshes/Back_Right_Wheel_Connect_L.STL" />
      </geometry>
      <material
        name="">
        <color
          rgba="1 0 0 1" />
      </material>
    </visual>
    <collision>
      <origin
        xyz="0 0 0"
        rpy="0 0 0" />
      <geometry>
        <mesh
          filename="package://prototype_urdf2/meshes/Back_Right_Wheel_Connect_L.STL" />
      </geometry>
    </collision>
  </link>
  <joint
    name="BRLA_joint_BRWC"
    type="revolute">
    <origin
      xyz="0 -0.088385 -0.0097003"
      rpy="-0.21347 0 0" />
    <parent
      link="Back_Right_Lower_Arm" />
    <child
      link="Back_Right_Wheel_Connect_L" />
    <axis
      xyz="-1 0 0" />
    <limit
      lower="0"
      upper="0"
      effort="0"
      velocity="0" />
  </joint>
  <link
    name="Back_Right_Suspension">
    <inertial>
      <origin
        xyz="-0.0250501195396812 0.00532528573434388 0.0578364361373782"
        rpy="0 0 0" />
      <mass
        value="0.0975010516337173" />
      <inertia
        ixx="7.92535130270421E-06"
        ixy="2.40205751875972E-09"
        ixz="2.07721001720319E-08"
        iyy="1.85918479783725E-05"
        iyz="-7.23412240509219E-07"
        izz="1.24383810777076E-05" />
    </inertial>
    <visual>
      <origin
        xyz="0 0 0"
        rpy="0 0 0" />
      <geometry>
        <mesh
          filename="package://prototype_urdf2/meshes/Back_Right_Suspension.STL" />
      </geometry>
      <material
        name="">
        <color
          rgba="0.752941176470588 0.752941176470588 0.752941176470588 1" />
      </material>
    </visual>
    <collision>
      <origin
        xyz="0 0 0"
        rpy="0 0 0" />
      <geometry>
        <mesh
          filename="package://prototype_urdf2/meshes/Back_Right_Suspension.STL" />
      </geometry>
    </collision>
  </link>
  <joint
    name="base_joint_BRS"
    type="prismatic">
    <origin
      xyz="-0.16528 0.19306 0.13323"
      rpy="1.6863 -1.1874 0" />
    <parent
      link="base_link" />
    <child
      link="Back_Right_Suspension" />
    <axis
      xyz="0 -0.11521 -0.99334" />
    <limit
      lower="-0.04"
      upper="0"
      effort="1000"
      velocity="1000" />
  </joint>
  <link
    name="Back_Right_Lower_Arm_S">
    <inertial>
      <origin
        xyz="-4.16333634234434E-16 -0.0151034357011682 -0.000327671875581984"
        rpy="0 0 0" />
      <mass
        value="0.0377520303994239" />
      <inertia
        ixx="2.67333578708892E-05"
        ixy="1.12227954004255E-20"
        ixz="-3.32135601854727E-21"
        iyy="6.42816105258092E-05"
        iyz="9.49601878939576E-06"
        izz="8.14259417304866E-05" />
    </inertial>
    <visual>
      <origin
        xyz="0 0 0"
        rpy="0 0 0" />
      <geometry>
        <mesh
          filename="package://prototype_urdf2/meshes/Back_Right_Lower_Arm_S.STL" />
      </geometry>
      <material
        name="">
        <color
          rgba="1 1 1 1" />
      </material>
    </visual>
    <collision>
      <origin
        xyz="0 0 0"
        rpy="0 0 0" />
      <geometry>
        <mesh
          filename="package://prototype_urdf2/meshes/Back_Right_Lower_Arm_S.STL" />
      </geometry>
    </collision>
  </link>
  <joint
    name="BRS_joint_BRLA"
    type="fixed">
    <origin
      xyz="-0.073326 -0.039657 0.063053"
      rpy="1.4009 1.4553 -1.5708" />
    <parent
      link="Back_Right_Suspension" />
    <child
      link="Back_Right_Lower_Arm_S" />
    <axis
      xyz="-1 0 0" />
  </joint>
</robot>